Workbook

Sheet Product Backlog
A1: Product Backlog – Capstone 5G FWA Rural | N1: Resumen por Sprint
N2: Sprint | O2: Tareas | P2: Estimación (h) | Q2: Finalizadas
N3: Sprint 1 | O3: =COUNTIF(D11:D94,1) -> 12 | P3: =SUMIF(D11:D94,1,H11:H94) -> 12.5 | Q3: =COUNTIFS(D11:D94,1,K11:K94,"Finalizado") -> 12
A4: Total tareas | B4: =COUNTA(A11:A94) -> 84 | C4: Estimación total (h) | D4: =SUM(H11:H94) -> 137.5 | E4: Finalizadas | F4: =COUNTIF(K11:K94,"Finalizado") -> 36 | G4: Pendientes | H4: =COUNTIF(K11:K94,"Pendiente") -> 43 | I4: Esfuerzo real (h) | J4: =SUM(I11:I94) -> 68 | K4: Esfuerzo restante (h) | L4: =SUM(J11:J94) -> 69.5 | N4: Sprint 2 | O4: =COUNTIF(D11:D94,2) -> 14 | P4: =SUMIF(D11:D94,2,H11:H94) -> 23.5 | Q4: =COUNTIFS(D11:D94,2,K11:K94,"Finalizado") -> 14
N5: Sprint 3 | O5: =COUNTIF(D11:D94,3) -> 10 | P5: =SUMIF(D11:D94,3,H11:H94) -> 17.5 | Q5: =COUNTIFS(D11:D94,3,K11:K94,"Finalizado") -> 10
N6: Sprint 4 | O6: =COUNTIF(D11:D94,4) -> 10 | P6: =SUMIF(D11:D94,4,H11:H94) -> 22.5 | Q6: =COUNTIFS(D11:D94,4,K11:K94,"Finalizado") -> 0
N7: Sprint 5 | O7: =COUNTIF(D11:D94,5) -> 18 | P7: =SUMIF(D11:D94,5,H11:H94) -> 24.5 | Q7: =COUNTIFS(D11:D94,5,K11:K94,"Finalizado") -> 0
N8: Sprint 6 | O8: =COUNTIF(D11:D94,6) -> 20 | P8: =SUMIF(D11:D94,6,H11:H94) -> 37 | Q8: =COUNTIFS(D11:D94,6,K11:K94,"Finalizado") -> 0
A10: ID | B10: Product Backlog Item | C10: Fecha definición | D10: Sprint objetivo | E10: Prioridad | F10: Riesgo | G10: Valor | H10: Estimación trabajo (h-persona) | I10: Esfuerzo real (h-persona) | J10: Esfuerzo restante (h-persona) | K10: Estado | L10: Responsable(s) | M10: Notas
A11: PB01 | B11: Organizar repositorio GitHub y estructura del proyecto | C11: 46250 | D11: 1 | E11: Alta | F11: Bajo | G11: Alto | H11: 1 | I11: 1 | J11: ='Sprint 1'!G10 -> 0 | K11: ='Sprint 1'!H10 -> Finalizado | L11: =IF('Sprint 1'!C10="","",'Sprint 1'!C10) -> Felipe | M11: =IF('Sprint 1'!K10="","",'Sprint 1'!K10) -> Realizado con éxito
A12: PB02 | B12: Revisar estructura y contenido del dataset suministrado | C12: 46250 | D12: 1 | E12: Alta | F12: Bajo | G12: Alto | H12: 1 | I12: 1 | J12: ='Sprint 1'!G11 -> 0 | K12: ='Sprint 1'!H11 -> Finalizado | L12: =IF('Sprint 1'!C11="","",'Sprint 1'!C11) -> Felipe | M12: =IF('Sprint 1'!K11="","",'Sprint 1'!K11) -> Realizado con éxito
A13: PB03 | B13: Configurar entorno Python/Jupyter para ejecutar el notebook | C13: 46250 | D13: 1 | E13: Alta | F13: Bajo | G13: Alto | H13: 1 | I13: 1 | J13: ='Sprint 1'!G12 -> 0 | K13: ='Sprint 1'!H12 -> Finalizado | L13: =IF('Sprint 1'!C12="","",'Sprint 1'!C12) -> Felipe | M13: =IF('Sprint 1'!K12="","",'Sprint 1'!K12) -> Realizado con éxito
A14: PB04 | B14: Ejecutar y reproducir completamente el baseline suministrado | C14: 46250 | D14: 1 | E14: Alta | F14: Bajo | G14: Alto | H14: 2 | I14: 2 | J14: ='Sprint 1'!G13 -> 0 | K14: ='Sprint 1'!H13 -> Finalizado | L14: =IF('Sprint 1'!C13="","",'Sprint 1'!C13) -> Felipe | M14: =IF('Sprint 1'!K13="","",'Sprint 1'!K13) -> Realizado con éxito
A15: PB05 | B15: Registrar métricas iniciales del baseline | C15: 46250 | D15: 1 | E15: Alta | F15: Bajo | G15: Alto | H15: 0.5 | I15: 0.5 | J15: ='Sprint 1'!G14 -> 0 | K15: ='Sprint 1'!H14 -> Finalizado | L15: =IF('Sprint 1'!C14="","",'Sprint 1'!C14) -> Felipe | M15: =IF('Sprint 1'!K14="","",'Sprint 1'!K14) -> Realizado con éxito
A16: PB06 | B16: Documentar parámetros y supuestos del escenario base | C16: 46250 | D16: 1 | E16: Alta | F16: Bajo | G16: Alto | H16: 1 | I16: 1 | J16: ='Sprint 1'!G15 -> 0 | K16: ='Sprint 1'!H15 -> Finalizado | L16: =IF('Sprint 1'!C15="","",'Sprint 1'!C15) -> Felipe | M16: =IF('Sprint 1'!K15="","",'Sprint 1'!K15) -> Realizado con éxito
A17: PB07 | B17: Realizar sanity checks sobre dataset y baseline | C17: 46250 | D17: 1 | E17: Alta | F17: Bajo | G17: Alto | H17: 1 | I17: 1 | J17: ='Sprint 1'!G16 -> 0 | K17: ='Sprint 1'!H16 -> Finalizado | L17: =IF('Sprint 1'!C16="","",'Sprint 1'!C16) -> Felipe | M17: =IF('Sprint 1'!K16="","",'Sprint 1'!K16) -> Realizado con éxito
A18: PB08 | B18: Identificar y documentar inconsistencias o hallazgos del baseline | C18: 46250 | D18: 1 | E18: Alta | F18: Bajo | G18: Alto | H18: 1 | I18: 1 | J18: ='Sprint 1'!G17 -> 0 | K18: ='Sprint 1'!H17 -> Finalizado | L18: =IF('Sprint 1'!C17="","",'Sprint 1'!C17) -> Felipe | M18: =IF('Sprint 1'!K17="","",'Sprint 1'!K17) -> Realizado con éxito
A19: PB09 | B19: Documentar procedimiento para reproducir el baseline | C19: 46250 | D19: 1 | E19: Alta | F19: Bajo | G19: Alto | H19: 0.5 | I19: 0.5 | J19: ='Sprint 1'!G18 -> 0 | K19: ='Sprint 1'!H18 -> Finalizado | L19: =IF('Sprint 1'!C18="","",'Sprint 1'!C18) -> Felipe | M19: =IF('Sprint 1'!K18="","",'Sprint 1'!K18) -> Realizado con éxito
A20: PB10 | B20: Crear y priorizar el Product Backlog | C20: 46250 | D20: 1 | E20: Alta | F20: Bajo | G20: Alto | H20: 2 | I20: 2 | J20: ='Sprint 1'!G19 -> 0 | K20: ='Sprint 1'!H19 -> Finalizado | L20: =IF('Sprint 1'!C19="","",'Sprint 1'!C19) -> Jhon | M20: =IF('Sprint 1'!K19="","",'Sprint 1'!K19) -> Realizado con éxito
A21: PB11 | B21: Verificar reproducibilidad del baseline desde otro integrante/equipo | C21: 46250 | D21: 1 | E21: Alta | F21: Bajo | G21: Alto | H21: 1 | I21: =IF('Sprint 1'!F20="","",'Sprint 1'!F20) -> 1 | J21: ='Sprint 1'!G20 -> 0 | K21: ='Sprint 1'!H20 -> Finalizado | L21: =IF('Sprint 1'!C20="","",'Sprint 1'!C20) -> Emanuel/Jhon | M21: =IF('Sprint 1'!K20="","",'Sprint 1'!K20) -> Realizado con éxito
A22: PB12 | B22: Registrar evidencias y estado final del Sprint 1 | C22: 46250 | D22: 1 | E22: Media | F22: Bajo | G22: Alto | H22: 0.5 | I22: =IF('Sprint 1'!F21="","",'Sprint 1'!F21) -> 0.5 | J22: ='Sprint 1'!G21 -> 0 | K22: ='Sprint 1'!H21 -> Finalizado | L22: =IF('Sprint 1'!C21="","",'Sprint 1'!C21) -> Felipe | M22: =IF('Sprint 1'!K21="","",'Sprint 1'!K21) -> Realizado con éxito
A23: PB13 | B23: Revisar formalmente el modelo de asociación por mejor RSRP | C23: 46250 | D23: 2 | E23: Alta | F23: Bajo | G23: Alto | H23: 1 | I23: =IF('Sprint 2'!F10="","",'Sprint 2'!F10) -> 1 | J23: ='Sprint 2'!G10 -> 0 | K23: ='Sprint 2'!H10 -> Finalizado | L23: =IF('Sprint 2'!C10="","",'Sprint 2'!C10) -> Felipe | M23: =IF('Sprint 2'!K10="","",'Sprint 2'!K10) -> Realizado con éxito
A24: PB14 | B24: Revisar e implementar correctamente el cálculo de interferencia reuse-1 | C24: 46250 | D24: 2 | E24: Alta | F24: Bajo | G24: Alto | H24: 2 | I24: =IF('Sprint 2'!F11="","",'Sprint 2'!F11) -> 2 | J24: ='Sprint 2'!G11 -> 0 | K24: ='Sprint 2'!H11 -> Finalizado | L24: =IF('Sprint 2'!C11="","",'Sprint 2'!C11) -> Felipe | M24: =IF('Sprint 2'!K11="","",'Sprint 2'!K11) -> Realizado con éxito
A25: PB15 | B25: Revisar e implementar el cálculo de SINR por punto de demanda | C25: 46250 | D25: 2 | E25: Alta | F25: Bajo | G25: Alto | H25: 2 | I25: =IF('Sprint 2'!F12="","",'Sprint 2'!F12) -> 2 | J25: ='Sprint 2'!G12 -> 0 | K25: ='Sprint 2'!H12 -> Finalizado | L25: =IF('Sprint 2'!C12="","",'Sprint 2'!C12) -> Felipe | M25: =IF('Sprint 2'!K12="","",'Sprint 2'!K12) -> Realizado con éxito
A26: PB16 | B26: Revisar cálculo de ruido térmico y unidades empleadas | C26: 46250 | D26: 2 | E26: Alta | F26: Bajo | G26: Alto | H26: 1 | I26: =IF('Sprint 2'!F13="","",'Sprint 2'!F13) -> 1 | J26: ='Sprint 2'!G13 -> 0 | K26: ='Sprint 2'!H13 -> Finalizado | L26: =IF('Sprint 2'!C13="","",'Sprint 2'!C13) -> Felipe | M26: =IF('Sprint 2'!K13="","",'Sprint 2'!K13) -> Realizado con éxito
A27: PB17 | B27: Revisar conversión SINR → eficiencia espectral | C27: 46250 | D27: 2 | E27: Alta | F27: Bajo | G27: Alto | H27: 1.5 | I27: =IF('Sprint 2'!F14="","",'Sprint 2'!F14) -> 1.5 | J27: ='Sprint 2'!G14 -> 0 | K27: ='Sprint 2'!H14 -> Finalizado | L27: =IF('Sprint 2'!C14="","",'Sprint 2'!C14) -> Jhon | M27: =IF('Sprint 2'!K14="","",'Sprint 2'!K14) -> Realizado con éxito
A28: PB18 | B28: Revisar e implementar cálculo de capacidad por punto | C28: 46250 | D28: 2 | E28: Alta | F28: Bajo | G28: Alto | H28: 2 | I28: =IF('Sprint 2'!F15="","",'Sprint 2'!F15) -> 2 | J28: ='Sprint 2'!G15 -> 0 | K28: ='Sprint 2'!H15 -> Finalizado | L28: =IF('Sprint 2'!C15="","",'Sprint 2'!C15) -> Jhon | M28: =IF('Sprint 2'!K15="","",'Sprint 2'!K15) -> Realizado con éxito
A29: PB19 | B29: Verificar cálculo de demanda en Busy Hour por punto | C29: 46250 | D29: 2 | E29: Alta | F29: Bajo | G29: Alto | H29: 1.5 | I29: =IF('Sprint 2'!F16="","",'Sprint 2'!F16) -> 1.5 | J29: ='Sprint 2'!G16 -> 0 | K29: ='Sprint 2'!H16 -> Finalizado | L29: =IF('Sprint 2'!C16="","",'Sprint 2'!C16) -> Jhon | M29: =IF('Sprint 2'!K16="","",'Sprint 2'!K16) -> Realizado con éxito
A30: PB20 | B30: Definir formalmente el criterio de cobertura poblacional | C30: 46250 | D30: 2 | E30: Alta | F30: Bajo | G30: Alto | H30: 2 | I30: =IF('Sprint 2'!F17="","",'Sprint 2'!F17) -> 2 | J30: ='Sprint 2'!G17 -> 0 | K30: ='Sprint 2'!H17 -> Finalizado | L30: =IF('Sprint 2'!C17="","",'Sprint 2'!C17) -> Felipe | M30: =IF('Sprint 2'!K17="","",'Sprint 2'!K17) -> Realizado con éxito
A31: PB21 | B31: Resolver discrepancia entre coverage_min_sinr_db y cobertura del baseline | C31: 46250 | D31: 2 | E31: Alta | F31: Bajo | G31: Alto | H31: 1.5 | I31: =IF('Sprint 2'!F18="","",'Sprint 2'!F18) -> 1.5 | J31: ='Sprint 2'!G18 -> 0 | K31: ='Sprint 2'!H18 -> Finalizado | L31: =IF('Sprint 2'!C18="","",'Sprint 2'!C18) -> Felipe | M31: =IF('Sprint 2'!K18="","",'Sprint 2'!K18) -> Realizado con éxito
A32: PB22 | B32: Implementar/verificar las métricas técnicas obligatorias | C32: 46250 | D32: 2 | E32: Alta | F32: Bajo | G32: Alto | H32: 2 | I32: =IF('Sprint 2'!F19="","",'Sprint 2'!F19) -> 2 | J32: ='Sprint 2'!G19 -> 0 | K32: ='Sprint 2'!H19 -> Finalizado | L32: =IF('Sprint 2'!C19="","",'Sprint 2'!C19) -> Emanuel | M32: =IF('Sprint 2'!K19="","",'Sprint 2'!K19) -> Realizado con éxito
A33: PB23 | B33: Crear pruebas y sanity checks del modelo técnico completo | C33: 46250 | D33: 2 | E33: Alta | F33: Bajo | G33: Alto | H33: 2 | I33: =IF('Sprint 2'!F20="","",'Sprint 2'!F20) -> 2 | J33: ='Sprint 2'!G20 -> 0 | K33: ='Sprint 2'!H20 -> Finalizado | L33: =IF('Sprint 2'!C20="","",'Sprint 2'!C20) -> Jhon | M33: =IF('Sprint 2'!K20="","",'Sprint 2'!K20) -> Realizado con éxito
A34: PB24 | B34: Crear visualización de puntos de demanda y sitios candidatos | C34: 46250 | D34: 2 | E34: Media | F34: Bajo | G34: Alto | H34: 1.5 | I34: =IF('Sprint 2'!F21="","",'Sprint 2'!F21) -> 1.5 | J34: ='Sprint 2'!G21 -> 0 | K34: ='Sprint 2'!H21 -> Finalizado | L34: =IF('Sprint 2'!C21="","",'Sprint 2'!C21) -> Emanuel | M34: =IF('Sprint 2'!K21="","",'Sprint 2'!K21) -> Realizado con éxito
... A36: PB26 | B36: Documentar resultados y validación del modelo técnico | C36: 46250 | D36: 2 | E36: Alta | F36: Bajo | G36: Alto | H36: 1.5 | I36: =IF('Sprint 2'!F23="","",'Sprint 2'!F23) -> 1.5 | J36: ='Sprint 2'!G23 -> 0 | K36: ='Sprint 2'!H23 -> Finalizado | L36: =IF('Sprint 2'!C23="","",'Sprint 2'!C23) -> Emanuel | M36: =IF('Sprint 2'!K23="","",'Sprint 2'!K23) -> Realizado con éxito
A37: PB27 | B37: Definir función objetivo para selección de sitios | C37: 46250 | D37: 3 | E37: Alta | F37: Bajo | G37: Alto | H37: 2 | I37: =IF('Sprint 3'!F10="","",'Sprint 3'!F10) -> 2 | J37: ='Sprint 3'!G10 -> 0 | K37: ='Sprint 3'!H10 -> Finalizado | L37: =IF('Sprint 3'!C10="","",'Sprint 3'!C10) -> Felipe | M37: =IF('Sprint 3'!K10="","",'Sprint 3'!K10) -> Terminado con éxito
A38: PB28 | B38: Analizar pesos de cobertura, capacidad y penalización por sitios | C38: 46250 | D38: 3 | E38: Alta | F38: Bajo | G38: Alto | H38: 1.5 | I38: =IF('Sprint 3'!F11="","",'Sprint 3'!F11) -> 1.5 | J38: ='Sprint 3'!G11 -> 0 | K38: ='Sprint 3'!H11 -> Finalizado | L38: =IF('Sprint 3'!C11="","",'Sprint 3'!C11) -> Felipe | M38: =IF('Sprint 3'!K11="","",'Sprint 3'!K11) -> Terminado con éxito
A39: PB29 | B39: Implementar algoritmo de optimización 1 | C39: 46250 | D39: 3 | E39: Alta | F39: Bajo | G39: Alto | H39: 3 | I39: =IF('Sprint 3'!F12="","",'Sprint 3'!F12) -> 3 | J39: ='Sprint 3'!G12 -> 0 | K39: ='Sprint 3'!H12 -> Finalizado | L39: =IF('Sprint 3'!C12="","",'Sprint 3'!C12) -> Felipe | M39: =IF('Sprint 3'!K12="","",'Sprint 3'!K12) -> Terminado con éxito
A40: PB30 | B40: Ejecutar algoritmo 1 para diferentes valores de S | C40: 46250 | D40: 3 | E40: Alta | F40: Bajo | G40: Alto | H40: 2 | I40: =IF('Sprint 3'!F13="","",'Sprint 3'!F13) -> 2 | J40: ='Sprint 3'!G13 -> 0 | K40: ='Sprint 3'!H13 -> Finalizado | L40: =IF('Sprint 3'!C13="","",'Sprint 3'!C13) -> Jhon | M40: =IF('Sprint 3'!K13="","",'Sprint 3'!K13) -> Terminado con éxito
A41: PB31 | B41: Comparar algoritmo 1 contra el baseline | C41: 46250 | D41: 3 | E41: Alta | F41: Bajo | G41: Alto | H41: 2 | I41: =IF('Sprint 3'!F14="","",'Sprint 3'!F14) -> 2 | J41: ='Sprint 3'!G14 -> 0 | K41: ='Sprint 3'!H14 -> Finalizado | L41: =IF('Sprint 3'!C14="","",'Sprint 3'!C14) -> Jhon | M41: =IF('Sprint 3'!K14="","",'Sprint 3'!K14) -> Terminado con éxito
A42: PB32 | B42: Analizar trade-off cobertura vs capacidad | C42: 46250 | D42: 3 | E42: Alta | F42: Bajo | G42: Alto | H42: 1.5 | I42: =IF('Sprint 3'!F15="","",'Sprint 3'!F15) -> 1.5 | J42: ='Sprint 3'!G15 -> 0 | K42: ='Sprint 3'!H15 -> Finalizado | L42: =IF('Sprint 3'!C15="","",'Sprint 3'!C15) -> Emanuel | M42: =IF('Sprint 3'!K15="","",'Sprint 3'!K15) -> Terminado con éxito
...

Sheet Sprint 1
A1: Sprint 1 – Semanas 1–2
A2: Objetivo | B2: Kick-off, comprensión del escenario, backlog y baseline reproducible. | G2: Tareas | H2: =COUNTA(A10:A21) -> 12
A3: Entregables mínimos | B3: Backlog priorizado, baseline del notebook ejecutado y métricas iniciales. | G3: Finalizadas | H3: =COUNTIF(H10:H21,"Finalizado") -> 12
A4: Definition of Done (DoD) | B4: Reproducibilidad, supuestos claros y repositorio organizado. | G4: Est. total (h) | H4: =SUM(E10:E21) -> 12.5
A5: Entrega | B5: 24-08 | G5: Real total (h) | H5: =SUM(F10:F21) -> 12.5
G6: Restante (h) | H6: =SUM(G10:G21) -> 0
A9: Backlog Item | B9: Sprint Task | C9: Volunteer / Responsable(s) | D9: Prioridad | E9: Initial Estimated Effort (h) | F9: Actual Effort (h) | G9: Effort Remaining (h) | H9: Estado | I9: Fecha inicio | J9: Fecha cierre | K9: Evidencia / Notas
A10: PB01 | B10: Organizar repositorio GitHub y estructura del proyecto | C10: Felipe | D10: Alta | E10: 1 | F10: 1 | G10: =IF(H10="Finalizado",0,MAX(E10-IF(F10="",0,F10),0)) -> 0 | H10: Finalizado | I10: 46250 | J10: 46251 | K10: Realizado con éxito
A11: PB02 | B11: Revisar estructura y contenido del dataset suministrado | C11: Felipe | D11: Alta | E11: 1 | F11: 1 | G11: =IF(H11="Finalizado",0,MAX(E11-IF(F11="",0,F11),0)) -> 0 | H11: Finalizado | I11: 46250 | J11: 46251 | K11: Realizado con éxito
A12: PB03 | B12: Configurar entorno Python/Jupyter para ejecutar el notebook | C12: Felipe | D12: Alta | E12: 1 | F12: 1 | G12: =IF(H12="Finalizado",0,MAX(E12-IF(F12="",0,F12),0)) -> 0 | H12: Finalizado | I12: 46250 | J12: 46251 | K12: Realizado con éxito
A13: PB04 | B13: Ejecutar y reproducir completamente el baseline suministrado | C13: Felipe | D13: Alta | E13: 2 | F13: 2 | G13: =IF(H13="Finalizado",0,MAX(E13-IF(F13="",0,F13),0)) -> 0 | H13: Finalizado | I13: 46250 | J13: 46251 | K13: Realizado con éxito
A14: PB05 | B14: Registrar métricas iniciales del baseline | C14: Felipe | D14: Alta | E14: 0.5 | F14: 0.5 | G14: =IF(H14="Finalizado",0,MAX(E14-IF(F14="",0,F14),0)) -> 0 | H14: Finalizado | I14: 46250 | J14: 46251 | K14: Realizado con éxito
A15: PB06 | B15: Documentar parámetros y supuestos del escenario base | C15: Felipe | D15: Alta | E15: 1 | F15: 1 | G15: =IF(H15="Finalizado",0,MAX(E15-IF(F15="",0,F15),0)) -> 0 | H15: Finalizado | I15: 46250 | J15: 46251 | K15: Realizado con éxito
A16: PB07 | B16: Realizar sanity checks sobre dataset y baseline | C16: Felipe | D16: Alta | E16: 1 | F16: 1 | G16: =IF(H16="Finalizado",0,MAX(E16-IF(F16="",0,F16),0)) -> 0 | H16: Finalizado | I16: 46250 | J16: 46251 | K16: Realizado con éxito
A17: PB08 | B17: Identificar y documentar inconsistencias o hallazgos del baseline | C17: Felipe | D17: Alta | E17: 1 | F17: 1 | G17: =IF(H17="Finalizado",0,MAX(E17-IF(F17="",0,F17),0)) -> 0 | H17: Finalizado | I17: 46250 | J17: 46251 | K17: Realizado con éxito
A18: PB09 | B18: Documentar procedimiento para reproducir el baseline | C18: Felipe | D18: Alta | E18: 0.5 | F18: 0.5 | G18: =IF(H18="Finalizado",0,MAX(E18-IF(F18="",0,F18),0)) -> 0 | H18: Finalizado | I18: 46250 | J18: 46251 | K18: Realizado con éxito
A19: PB10 | B19: Crear y priorizar el Product Backlog | C19: Jhon | D19: Alta | E19: 2 | F19: 2 | G19: =IF(H19="Finalizado",0,MAX(E19-IF(F19="",0,F19),0)) -> 0 | H19: Finalizado | I19: 46250 | J19: 46251 | K19: Realizado con éxito
A20: PB11 | B20: Verificar reproducibilidad del baseline desde otro integrante/equipo | C20: Emanuel/Jhon | D20: Alta | E20: 1 | F20: 1 | G20: =IF(H20="Finalizado",0,MAX(E20-IF(F20="",0,F20),0)) -> 0 | H20: Finalizado | I20: 46250 | J20: 46251 | K20: Realizado con éxito
A21: PB12 | B21: Registrar evidencias y estado final del Sprint 1 | C21: Felipe | D21: Media | E21: 0.5 | F21: 0.5 | G21: =IF(H21="Finalizado",0,MAX(E21-IF(F21="",0,F21),0)) -> 0 | H21: Finalizado | I21: 46250 | J21: 46251 | K21: Realizado con éxito

Sheet Sprint 2
A1: Sprint 2 – Semanas 3–4
A2: Objetivo | B2: Modelo técnico completo (SINR/capacidad) y métricas por punto. | G2: Tareas | H2: =COUNTA(A10:A23) -> 14
A3: Entregables mínimos | B3: Funciones de evaluación, reporte de métricas baseline y visualizaciones básicas. | G3: Finalizadas | H3: =COUNTIF(H10:H23,"Finalizado") -> 14
A4: Definition of Done (DoD) | B4: Correctitud del modelo, métricas coherentes y pruebas. | G4: Est. total (h) | H4: =SUM(E10:E23) -> 23.5
A5: Entrega | B5: — | G5: Real total (h) | H5: =SUM(F10:F23) -> 23.5
G6: Restante (h) | H6: =SUM(G10:G23) -> 0
A9: Backlog Item | B9: Sprint Task | C9: Volunteer / Responsable(s) | D9: Prioridad | E9: Initial Estimated Effort (h) | F9: Actual Effort (h) | G9: Effort Remaining (h) | H9: Estado | I9: Fecha inicio | J9: Fecha cierre | K9: Evidencia / Notas
A10: PB13 | B10: Revisar formalmente el modelo de asociación por mejor RSRP | C10: Felipe | D10: Alta | E10: 1 | F10: 1 | G10: =IF(H10="Finalizado",0,MAX(E10-IF(F10="",0,F10),0)) -> 0 | H10: Finalizado | I10: 46263 | J10: 46269 | K10: Realizado con éxito
A11: PB14 | B11: Revisar e implementar correctamente el cálculo de interferencia reuse-1 | C11: Felipe | D11: Alta | E11: 2 | F11: 2 | G11: =IF(H11="Finalizado",0,MAX(E11-IF(F11="",0,F11),0)) -> 0 | H11: Finalizado | I11: 46263 | J11: 46269 | K11: Realizado con éxito
A12: PB15 | B12: Revisar e implementar el cálculo de SINR por punto de demanda | C12: Felipe | D12: Alta | E12: 2 | F12: 2 | G12: =IF(H12="Finalizado",0,MAX(E12-IF(F12="",0,F12),0)) -> 0 | H12: Finalizado | I12: 46263 | J12: 46269 | K12: Realizado con éxito
A13: PB16 | B13: Revisar cálculo de ruido térmico y unidades empleadas | C13: Felipe | D13: Alta | E13: 1 | F13: 1 | G13: =IF(H13="Finalizado",0,MAX(E13-IF(F13="",0,F13),0)) -> 0 | H13: Finalizado | I13: 46263 | J13: 46269 | K13: Realizado con éxito
A14: PB17 | B14: Revisar conversión SINR → eficiencia espectral | C14: Jhon | D14: Alta | E14: 1.5 | F14: 1.5 | G14: =IF(H14="Finalizado",0,MAX(E14-IF(F14="",0,F14),0)) -> 0 | H14: Finalizado | I14: 46271 | J14: 46273 | K14: Realizado con éxito
A15: PB18 | B15: Revisar e implementar cálculo de capacidad por punto | C15: Jhon | D15: Alta | E15: 2 | F15: 2 | G15: =IF(H15="Finalizado",0,MAX(E15-IF(F15="",0,F15),0)) -> 0 | H15: Finalizado | I15: 46271 | J15: 46273 | K15: Realizado con éxito
A16: PB19 | B16: Verificar cálculo de demanda en Busy Hour por punto | C16: Jhon | D16: Alta | E16: 1.5 | F16: 1.5 | G16: =IF(H16="Finalizado",0,MAX(E16-IF(F16="",0,F16),0)) -> 0 | H16: Finalizado | I16: 46271 | J16: 46273 | K16: Realizado con éxito
A17: PB20 | B17: Definir formalmente el criterio de cobertura poblacional | C17: Felipe | D17: Alta | E17: 2 | F17: 2 | G17: =IF(H17="Finalizado",0,MAX(E17-IF(F17="",0,F17),0)) -> 0 | H17: Finalizado | I17: 46269 | J17: 46270 | K17: Realizado con éxito
A18: PB21 | B18: Resolver discrepancia entre coverage_min_sinr_db y cobertura del baseline | C18: Felipe | D18: Alta | E18: 1.5 | F18: 1.5 | G18: =IF(H18="Finalizado",0,MAX(E18-IF(F18="",0,F18),0)) -> 0 | H18: Finalizado | I18: 46269 | J18: 46270 | K18: Realizado con éxito
A19: PB22 | B19: Implementar/verificar las métricas técnicas obligatorias | C19: Emanuel | D19: Alta | E19: 2 | F19: 2 | G19: =IF(H19="Finalizado",0,MAX(E19-IF(F19="",0,F19),0)) -> 0 | H19: Finalizado | I19: 46272 | J19: 46274 | K19: Realizado con éxito
A20: PB23 | B20: Crear pruebas y sanity checks del modelo técnico completo | C20: Jhon | D20: Alta | E20: 2 | F20: 2 | G20: =IF(H20="Finalizado",0,MAX(E20-IF(F20="",0,F20),0)) -> 0 | H20: Finalizado | I20: 46271 | J20: 46273 | K20: Realizado con éxito
A21: PB24 | B21: Crear visualización de puntos de demanda y sitios candidatos | C21: Emanuel | D21: Media | E21: 1.5 | F21: 1.5 | G21: =IF(H21="Finalizado",0,MAX(E21-IF(F21="",0,F21),0)) -> 0 | H21: Finalizado | I21: 46272 | J21: 46274 | K21: Realizado con éxito
... A23: PB26 | B23: Documentar resultados y validación del modelo técnico | C23: Emanuel | D23: Alta | E23: 1.5 | F23: 1.5 | G23: =IF(H23="Finalizado",0,MAX(E23-IF(F23="",0,F23),0)) -> 0 | H23: Finalizado | I23: 46272 | J23: 46274 | K23: Realizado con éxito

Sheet Sprint 3
A1: Sprint 3 – Semanas 5–6
A2: Objetivo | B2: Primera optimización (heurística/greedy/búsqueda local) con comparación. | G2: Tareas | H2: =COUNTA(A10:A19) -> 10
A3: Entregables mínimos | B3: Algoritmo 1, comparación vs baseline y análisis de trade-offs. | G3: Finalizadas | H3: =COUNTIF(H10:H19,"Finalizado") -> 10
A4: Definition of Done (DoD) | B4: Mejora cuantitativa, explicación y complejidad razonable. | G4: Est. total (h) | H4: =SUM(E10:E19) -> 17.5
A5: Entrega | B5: 21-09 | G5: Real total (h) | H5: =SUM(F10:F19) -> 17.5
G6: Restante (h) | H6: =SUM(G10:G19) -> 0
A9: Backlog Item | B9: Sprint Task | C9: Volunteer / Responsable(s) | D9: Prioridad | E9: Initial Estimated Effort (h) | F9: Actual Effort (h) | G9: Effort Remaining (h) | H9: Estado | I9: Fecha inicio | J9: Fecha cierre | K9: Evidencia / Notas
A10: PB27 | B10: Definir función objetivo para selección de sitios | C10: Felipe | D10: Alta | E10: 2 | F10: 2 | G10: =IF(H10="Finalizado",0,MAX(E10-IF(F10="",0,F10),0)) -> 0 | H10: Finalizado | I10: 46277 | J10: 46280 | K10: Terminado con éxito
A11: PB28 | B11: Analizar pesos de cobertura, capacidad y penalización por sitios | C11: Felipe | D11: Alta | E11: 1.5 | F11: 1.5 | G11: =IF(H11="Finalizado",0,MAX(E11-IF(F11="",0,F11),0)) -> 0 | H11: Finalizado | I11: 46277 | J11: 46280 | K11: Terminado con éxito
A12: PB29 | B12: Implementar algoritmo de optimización 1 | C12: Felipe | D12: Alta | E12: 3 | F12: 3 | G12: =IF(H12="Finalizado",0,MAX(E12-IF(F12="",0,F12),0)) -> 0 | H12: Finalizado | I12: 46277 | J12: 46280 | K12: Terminado con éxito
A13: PB30 | B13: Ejecutar algoritmo 1 para diferentes valores de S | C13: Jhon | D13: Alta | E13: 2 | F13: 2 | G13: =IF(H13="Finalizado",0,MAX(E13-IF(F13="",0,F13),0)) -> 0 | H13: Finalizado | I13: 46280 | J13: 46282 | K13: Terminado con éxito
A14: PB31 | B14: Comparar algoritmo 1 contra el baseline | C14: Jhon | D14: Alta | E14: 2 | F14: 2 | G14: =IF(H14="Finalizado",0,MAX(E14-IF(F14="",0,F14),0)) -> 0 | H14: Finalizado | I14: 46280 | J14: 46282 | K14: Terminado con éxito
A15: PB32 | B15: Analizar trade-off cobertura vs capacidad | C15: Emanuel | D15: Alta | E15: 1.5 | F15: 1.5 | G15: =IF(H15="Finalizado",0,MAX(E15-IF(F15="",0,F15),0)) -> 0 | H15: Finalizado | I15: 46281 | J15: 46285 | K15: Terminado con éxito
A16: PB33 | B16: Analizar trade-off calidad/interferencia vs número de sitios | C16: Emanuel | D16: Alta | E16: 1.5 | F16: 1.5 | G16: =IF(H16="Finalizado",0,MAX(E16-IF(F16="",0,F16),0)) -> 0 | H16: Finalizado | I16: 46281 | J16: 46285 | K16: Terminado con éxito
A17: PB34 | B17: Analizar mejora cuantitativa obtenida por algoritmo 1 | C17: Jhon | D17: Alta | E17: 1 | F17: 1 | G17: =IF(H17="Finalizado",0,MAX(E17-IF(F17="",0,F17),0)) -> 0 | H17: Finalizado | I17: 46281 | J17: 46282 | K17: Terminado con éxito
A18: PB35 | B18: Analizar y documentar complejidad del algoritmo 1 | C18: Felipe | D18: Media | E18: 1.5 | F18: 1.5 | G18: =IF(H18="Finalizado",0,MAX(E18-IF(F18="",0,F18),0)) -> 0 | H18: Finalizado | I18: 46277 | J18: 46285 | K18: Terminado con éxito
A19: PB36 | B19: Crear tablas/gráficas comparativas baseline vs algoritmo 1 | C19: Emanuel | D19: Media | E19: 1.5 | F19: 1.5 | G19: =IF(H19="Finalizado",0,MAX(E19-IF(F19="",0,F19),0)) -> 0 | H19: Finalizado | I19: 46281 | J19: 46285 | K19: Terminado con éxito

Sheet Sprint 4
A1: Sprint 4 – Semanas 7–8
A2: Objetivo | B2: Optimización mejorada (RL/imitación/ML o heurística avanzada) + robustez. | G2: Tareas | H2: =COUNTA(A10:A19) -> 10
A3: Entregables mínimos | B3: Algoritmo 2 y análisis de sensibilidad (S, pesos, umbrales). | G3: Finalizadas | H3: =COUNTIF(H10:H19,"Finalizado") -> 0
A4: Definition of Done (DoD) | B4: Estabilidad y generalización dentro del escenario. | G4: Est. total (h) | H4: =SUM(E10:E19) -> 22.5
A5: Entrega | B5: — | G5: Real total (h) | H5: =SUM(F10:F19) -> 14.5
G6: Restante (h) | H6: =SUM(G10:G19) -> 8
A9: Backlog Item | B9: Sprint Task | C9: Volunteer / Responsable(s) | D9: Prioridad | E9: Initial Estimated Effort (h) | F9: Actual Effort (h) | G9: Effort Remaining (h) | H9: Estado | I9: Fecha inicio | J9: Fecha cierre | K9: Evidencia / Notas
A10: PB37 | B10: Diseñar estrategia de optimización 2 mejorada | C10: Felipe | D10: Alta | E10: 3 | G10: =IF(H10="Finalizado",0,MAX(E10-IF(F10="",0,F10),0)) -> 3 | H10: Pendiente
A11: PB38 | B11: Implementar algoritmo de optimización 2 | C11: Felipe | D11: Alta | E11: 4 | G11: =IF(H11="Finalizado",0,MAX(E11-IF(F11="",0,F11),0)) -> 4 | H11: Pendiente
A12: PB39 | B12: Comparar algoritmo 2 contra baseline y algoritmo 1 | C12: Jhon | D12: Alta | E12: 2 | F12: 2 | G12: =IF(H12="Finalizado",0,MAX(E12-IF(F12="",0,F12),0)) -> 0 | H12: Validación | I12: 46302 | J12: 46304
A13: PB40 | B13: Analizar sensibilidad frente al número de sitios S | C13: Jhon | D13: Alta | E13: 2 | F13: 2 | G13: =IF(H13="Finalizado",0,MAX(E13-IF(F13="",0,F13),0)) -> 0 | H13: Validación | I13: 46302 | J13: 46304
A14: PB41 | B14: Analizar sensibilidad frente a pesos de la función objetivo | C14: Jhon | D14: Alta | E14: 2 | F14: 2 | G14: =IF(H14="Finalizado",0,MAX(E14-IF(F14="",0,F14),0)) -> 0 | H14: Validación | I14: 46302 | J14: 46304
A15: PB42 | B15: Analizar sensibilidad frente a umbrales técnicos | C15: Jhon | D15: Alta | E15: 2 | F15: 2 | G15: =IF(H15="Finalizado",0,MAX(E15-IF(F15="",0,F15),0)) -> 0 | H15: Validación | I15: 46302 | J15: 46304
A16: PB43 | B16: Evaluar estabilidad/robustez de las soluciones | C16: Jhon | D16: Alta | E16: 2 | F16: 2 | G16: =IF(H16="Finalizado",0,MAX(E16-IF(F16="",0,F16),0)) -> 0 | H16: Validación | I16: 46302 | J16: 46304
A17: PB44 | B17: Identificar diseño(s) técnicamente candidatos para decisión final | C17: Emanuel | D17: Alta | E17: 1.5 | F17: 1 | G17: =IF(H17="Finalizado",0,MAX(E17-IF(F17="",0,F17),0)) -> 0.5 | H17: Pendiente | I17: 46304 | J17: 46305
A18: PB45 | B18: Crear visualizaciones comparativas de optimización y sensibilidad | C18: Emanuel | D18: Media | E18: 2 | F18: 1.5 | G18: =IF(H18="Finalizado",0,MAX(E18-IF(F18="",0,F18),0)) -> 0.5 | H18: Pendiente | I18: 46304 | J18: 46305
A19: PB46 | B19: Documentar metodología y resultados de optimización mejorada | C19: Emanuel | D19: Alta | E19: 2 | F19: 2 | G19: =IF(H19="Finalizado",0,MAX(E19-IF(F19="",0,F19),0)) -> 0 | H19: Pendiente | I19: 46304 | J19: 46305

Sheet Sprint 5
A1: Sprint 5 – Semanas 9–10
A2: Objetivo | B2: Modelo económico completo + escenarios. | G2: Tareas | H2: =COUNTA(A10:A27) -> 18
A3: Entregables mínimos | B3: XLSX diligenciado, NPV/ROI/payback y escenarios ARPU/CAPEX/OPEX. | G3: Finalizadas | H3: =COUNTIF(H10:H27,"Finalizado") -> 0
A4: Definition of Done (DoD) | B4: Consistencia financiera, fuentes y sensibilidad. | G4: Est. total (h) | H4: =SUM(E10:E27) -> 24.5
A5: Entrega | B5: 19-10 | G5: Real total (h) | H5: =SUM(F10:F27) -> 0
G6: Restante (h) | H6: =SUM(G10:G27) -> 24.5
A9: Backlog Item | B9: Sprint Task | C9: Volunteer / Responsable(s) | D9: Prioridad | E9: Initial Estimated Effort (h) | F9: Actual Effort (h) | G9: Effort Remaining (h) | H9: Estado | I9: Fecha inicio | J9: Fecha cierre | K9: Evidencia / Notas
A10: PB47 | B10: Seleccionar diseño técnico que se llevará al modelo económico | C10: Felipe | D10: Alta | E10: 1 | G10: =IF(H10="Finalizado",0,MAX(E10-IF(F10="",0,F10),0)) -> 1 | H10: Pendiente
A11: PB48 | B11: Revisar interfaz notebook → modelo financiero XLSX | C11: Felipe | D11: Alta | E11: 1 | G11: =IF(H11="Finalizado",0,MAX(E11-IF(F11="",0,F11),0)) -> 1 | H11: Pendiente
A12: PB49 | B12: Resolver/justificar diferencia de suscriptores iniciales 711 vs 720 | C12: Felipe | D12: Alta | E12: 1 | G12: =IF(H12="Finalizado",0,MAX(E12-IF(F12="",0,F12),0)) -> 1 | H12: Pendiente
A13: PB50 | B13: Definir y justificar supuestos económicos utilizados | C13: Felipe | D13: Alta | E13: 2 | G13: =IF(H13="Finalizado",0,MAX(E13-IF(F13="",0,F13),0)) -> 2 | H13: Pendiente
A14: PB51 | B14: Transferir número de sitios, cobertura y capacidad al XLSX | C14: Felipe | D14: Alta | E14: 1 | G14: =IF(H14="Finalizado",0,MAX(E14-IF(F14="",0,F14),0)) -> 1 | H14: Pendiente
A15: PB52 | B15: Validar cálculo de CAPEX del proyecto | C15: Felipe | D15: Alta | E15: 1.5 | G15: =IF(H15="Finalizado",0,MAX(E15-IF(F15="",0,F15),0)) -> 1.5 | H15: Pendiente
A16: PB53 | B16: Validar cálculo de OPEX anual | C16: Felipe | D16: Alta | E16: 1.5 | G16: =IF(H16="Finalizado",0,MAX(E16-IF(F16="",0,F16),0)) -> 1.5 | H16: Pendiente
A17: PB54 | B17: Validar ingresos y suscriptores atendidos | C17: Emanuel | D17: Alta | E17: 1.5 | G17: =IF(H17="Finalizado",0,MAX(E17-IF(F17="",0,F17),0)) -> 1.5 | H17: Pendiente
A18: PB55 | B18: Obtener y validar flujo de caja a cinco años | C18: Emanuel | D18: Alta | E18: 1.5 | G18: =IF(H18="Finalizado",0,MAX(E18-IF(F18="",0,F18),0)) -> 1.5 | H18: Pendiente
A19: PB56 | B19: Calcular e interpretar NPV/VPN | C19: Emanuel | D19: Alta | E19: 1 | G19: =IF(H19="Finalizado",0,MAX(E19-IF(F19="",0,F19),0)) -> 1 | H19: Pendiente
A20: PB57 | B20: Calcular e interpretar ROI simple | C20: Emanuel | D20: Alta | E20: 1 | G20: =IF(H20="Finalizado",0,MAX(E20-IF(F20="",0,F20),0)) -> 1 | H20: Pendiente
A21: PB58 | B21: Calcular e interpretar payback | C21: Emanuel | D21: Alta | E21: 1 | G21: =IF(H21="Finalizado",0,MAX(E21-IF(F21="",0,F21),0)) -> 1 | H21: Pendiente
... A27: PB64 | B27: Emitir conclusión técnico-económica del diseño seleccionado | C27: Jhon | D27: Alta | E27: 2 | G27: =IF(H27="Finalizado",0,MAX(E27-IF(F27="",0,F27),0)) -> 2 | H27: Pendiente

Sheet Sprint 6
A1: Sprint 6 – Semanas 11–12
A2: Objetivo | B2: Integración final y presentación ejecutiva. | G2: Tareas | H2: =COUNTA(A10:A29) -> 20
A3: Entregables mínimos | B3: Informe final + demo notebook + pitch 15 min + retrospectiva Scrum. | G3: Finalizadas | H3: =COUNTIF(H10:H29,"Finalizado") -> 0
A4: Definition of Done (DoD) | B4: Historia clara, resultados defendibles y trazabilidad IA. | G4: Est. total (h) | H4: =SUM(E10:E29) -> 37
A5: Entrega | B5: 19-11 | G5: Real total (h) | H5: =SUM(F10:F29) -> 0
G6: Restante (h) | H6: =SUM(G10:G29) -> 37
A9: Backlog Item | B9: Sprint Task | C9: Volunteer / Responsable(s) | D9: Prioridad | E9: Initial Estimated Effort (h) | F9: Actual Effort (h) | G9: Effort Remaining (h) | H9: Estado | I9: Fecha inicio | J9: Fecha cierre | K9: Evidencia / Notas
A10: PB65 | B10: Integrar y depurar notebook final | D10: Alta | E10: 3 | G10: =IF(H10="Finalizado",0,MAX(E10-IF(F10="",0,F10),0)) -> 3 | H10: Pendiente
A11: PB66 | B11: Preparar notebook ejecutado para entrega | D11: Alta | E11: 1 | G11: =IF(H11="Finalizado",0,MAX(E11-IF(F11="",0,F11),0)) -> 1 | H11: Pendiente
A12: PB67 | B12: Preparar versión limpia del notebook sin outputs pesados | D12: Alta | E12: 1 | G12: =IF(H12="Finalizado",0,MAX(E12-IF(F12="",0,F12),0)) -> 1 | H12: Pendiente
A13: PB68 | B13: Consolidar resultados técnicos finales | D13: Alta | E13: 1.5 | G13: =IF(H13="Finalizado",0,MAX(E13-IF(F13="",0,F13),0)) -> 1.5 | H13: Pendiente
A14: PB69 | B14: Consolidar resultados económicos finales | D14: Alta | E14: 1.5 | G14: =IF(H14="Finalizado",0,MAX(E14-IF(F14="",0,F14),0)) -> 1.5 | H14: Pendiente
A15: PB70 | B15: Redactar informe final de máximo 6 páginas | D15: Alta | E15: 5 | G15: =IF(H15="Finalizado",0,MAX(E15-IF(F15="",0,F15),0)) -> 5 | H15: Pendiente
A16: PB71 | B16: Incluir metodología, resultados, discusión, economía y limitaciones en informe | D16: Alta | E16: 2 | G16: =IF(H16="Finalizado",0,MAX(E16-IF(F16="",0,F16),0)) -> 2 | H16: Pendiente
A17: PB72 | B17: Consolidar registro de prompts y uso de IA generativa | D17: Alta | E17: 1.5 | G17: =IF(H17="Finalizado",0,MAX(E17-IF(F17="",0,F17),0)) -> 1.5 | H17: Pendiente
A18: PB73 | B18: Documentar qué resultados de IA fueron aceptados o modificados y por qué | D18: Alta | E18: 1 | G18: =IF(H18="Finalizado",0,MAX(E18-IF(F18="",0,F18),0)) -> 1 | H18: Pendiente
A19: PB74 | B19: Documentar pruebas, sanity checks y validaciones realizadas | D19: Alta | E19: 1 | G19: =IF(H19="Finalizado",0,MAX(E19-IF(F19="",0,F19),0)) -> 1 | H19: Pendiente
A20: PB75 | B20: Preparar presentación final de 10–12 diapositivas | D20: Alta | E20: 4 | G20: =IF(H20="Finalizado",0,MAX(E20-IF(F20="",0,F20),0)) -> 4 | H20: Pendiente
A21: PB76 | B21: Preparar demo del notebook | D21: Alta | E21: 2 | G21: =IF(H21="Finalizado",0,MAX(E21-IF(F21="",0,F21),0)) -> 2 | H21: Pendiente
... A29: PB84 | B29: Realizar revisión final de todos los entregables | D29: Alta | E29: 2 | G29: =IF(H29="Finalizado",0,MAX(E29-IF(F29="",0,F29),0)) -> 2 | H29: Pendiente
